test_factorial (__main__.TestExercice) ... ok
test_prefixes (__main__.TestExercice) ... ok
test_summation (__main__.TestExercice) ... FAIL

======================================================================
FAIL: test_summation (__main__.TestExercice)
----------------------------------------------------------------------
Traceback (most recent call last):
  File "test_exercice.py", line 38, in test_summation
    'Retrait du mauvais caractère'
AssertionError: 76128 != 24133 : Retrait du mauvais caractère

----------------------------------------------------------------------
Ran 3 tests in 0.006s

FAILED (failures=1)
